[2020-04-28 16:31:12,629][ERROR][logg.relative_subcategory:233] No search   ()
Traceback (most recent call last):
  File "mysqlCon.py", line 228, in relative_subcategory
    data_dict=data_dict.update({data.get("id") : data.get("name")})
UnboundLocalError: local variable 'data_dict' referenced before assignment
[2020-04-28 16:31:12,631][ERROR][logg.main:304] Error connect to Mysql   ()
Traceback (most recent call last):
  File "mysqlCon.py", line 300, in main
    print(con.relative_subcategory("одежда"))
  File "mysqlCon.py", line 234, in relative_subcategory
    return data_dict
UnboundLocalError: local variable 'data_dict' referenced before assignment
