[2020-04-29 14:39:46,417][ERROR][logg.listProduct:304] no row   ()
Traceback (most recent call last):
  File "mysqlCon.py", line 301, in listProduct
    data_dict.upload(data)
AttributeError: 'NoneType' object has no attribute 'upload'
[2020-04-29 14:39:46,418][ERROR][logg.main:442] Error connect to Mysql   ()
Traceback (most recent call last):
  File "mysqlCon.py", line 301, in listProduct
    data_dict.upload(data)
AttributeError: 'NoneType' object has no attribute 'upload'

During handling of the above exception, another exception occurred:

Traceback (most recent call last):
  File "mysqlCon.py", line 438, in main
    print(con.listProduct(0,8))
  File "mysqlCon.py", line 305, in listProduct
    raise Exception("no row")
Exception: no row
