[2020-04-28 16:30:08,150][ERROR][logg.relative_subcategory:233] No search   ()
Traceback (most recent call last):
  File "mysqlCon.py", line 228, in relative_subcategory
    data_dict.update({data.get("id") : data.get("name")})
NameError: name 'data_dict' is not defined
[2020-04-28 16:30:08,152][ERROR][logg.main:304] Error connect to Mysql   ()
Traceback (most recent call last):
  File "mysqlCon.py", line 300, in main
    print(con.relative_subcategory("одежда"))
  File "mysqlCon.py", line 234, in relative_subcategory
    return data_dict
NameError: name 'data_dict' is not defined
