[2020-04-29 01:55:17,313][ERROR][logg.add_features_value:328] No search   ()
Traceback (most recent call last):
  File "mysqlCon.py", line 307, in add_features_value
    cursor.execute(sql, (value,id_feature, barcode))
  File "/Library/Frameworks/Python.framework/Versions/3.7/lib/python3.7/site-packages/pymysql/cursors.py", line 170, in execute
    result = self._query(query)
  File "/Library/Frameworks/Python.framework/Versions/3.7/lib/python3.7/site-packages/pymysql/cursors.py", line 328, in _query
    conn.query(q)
  File "/Library/Frameworks/Python.framework/Versions/3.7/lib/python3.7/site-packages/pymysql/connections.py", line 517, in query
    self._affected_rows = self._read_query_result(unbuffered=unbuffered)
  File "/Library/Frameworks/Python.framework/Versions/3.7/lib/python3.7/site-packages/pymysql/connections.py", line 732, in _read_query_result
    result.read()
  File "/Library/Frameworks/Python.framework/Versions/3.7/lib/python3.7/site-packages/pymysql/connections.py", line 1075, in read
    first_packet = self.connection._read_packet()
  File "/Library/Frameworks/Python.framework/Versions/3.7/lib/python3.7/site-packages/pymysql/connections.py", line 684, in _read_packet
    packet.check_error()
  File "/Library/Frameworks/Python.framework/Versions/3.7/lib/python3.7/site-packages/pymysql/protocol.py", line 220, in check_error
    err.raise_mysql_exception(self._data)
  File "/Library/Frameworks/Python.framework/Versions/3.7/lib/python3.7/site-packages/pymysql/err.py", line 109, in raise_mysql_exception
    raise errorclass(errno, errval)
pymysql.err.InternalError: (1364, "Field 'id_feature_value' doesn't have a default value")
