[2020-04-26 17:50:19,482][ERROR][logg.main:125] Error connect to Mysql   ()
Traceback (most recent call last):
  File "hash_1.py", line 121, in main
    con.registration_user()
  File "hash_1.py", line 77, in registration_user
    barcode = random.randint(100000000000,999999999999)
NameError: name 'random' is not defined
