[2020-04-26 00:01:31,186][ERROR][logg.product_info:233] No search   ()
Traceback (most recent call last):
  File "mysqlCon.py", line 227, in product_info
    dict_as_list.append(data.items())
NameError: name 'dict_as_list' is not defined
[2020-04-26 00:01:31,188][ERROR][logg.main:247] Error connect to Mysql   ()
Traceback (most recent call last):
  File "mysqlCon.py", line 243, in main
    print(con.product_info('733749933993'))
  File "mysqlCon.py", line 234, in product_info
    return dictionary
UnboundLocalError: local variable 'dictionary' referenced before assignment
