[2020-04-29 14:13:44,565][ERROR][logg.rowcount:284] has barcode   ()
Traceback (most recent call last):
  File "mysqlCon.py", line 278, in rowcount
    cursor.execute(sql0, (barcode))
NameError: name 'barcode' is not defined
[2020-04-29 14:13:44,567][ERROR][logg.main:422] Error connect to Mysql   ()
Traceback (most recent call last):
  File "mysqlCon.py", line 278, in rowcount
    cursor.execute(sql0, (barcode))
NameError: name 'barcode' is not defined

During handling of the above exception, another exception occurred:

Traceback (most recent call last):
  File "mysqlCon.py", line 418, in main
    print(con.rowcount())
  File "mysqlCon.py", line 285, in rowcount
    raise Exception("d")
Exception: d
