[2020-04-28 21:17:19,679][ERROR][logg.add_row_to_products:293] No search   ()
Traceback (most recent call last):
  File "mysqlCon.py", line 269, in add_row_to_products
    raise self.DoesNotExist
MySqlCon.DoesNotExist
[2020-04-28 21:17:19,684][ERROR][logg.add_features_value:326] No search   ()
Traceback (most recent call last):
  File "mysqlCon.py", line 305, in add_features_value
    cursor.execute(sql, (value,id_feature, barcode))
  File "C:\Users\User\AppData\Local\Packages\PythonSoftwareFoundation.Python.3.8_qbz5n2kfra8p0\LocalCache\local-packages\Python38\site-packages\pymysql\cursors.py", line 170, in execute
    result = self._query(query)
  File "C:\Users\User\AppData\Local\Packages\PythonSoftwareFoundation.Python.3.8_qbz5n2kfra8p0\LocalCache\local-packages\Python38\site-packages\pymysql\cursors.py", line 328, in _query
    conn.query(q)
  File "C:\Users\User\AppData\Local\Packages\PythonSoftwareFoundation.Python.3.8_qbz5n2kfra8p0\LocalCache\local-packages\Python38\site-packages\pymysql\connections.py", line 517, in query
    self._affected_rows = self._read_query_result(unbuffered=unbuffered)
  File "C:\Users\User\AppData\Local\Packages\PythonSoftwareFoundation.Python.3.8_qbz5n2kfra8p0\LocalCache\local-packages\Python38\site-packages\pymysql\connections.py", line 732, in _read_query_result
    result.read()
  File "C:\Users\User\AppData\Local\Packages\PythonSoftwareFoundation.Python.3.8_qbz5n2kfra8p0\LocalCache\local-packages\Python38\site-packages\pymysql\connections.py", line 1075, in read
    first_packet = self.connection._read_packet()
  File "C:\Users\User\AppData\Local\Packages\PythonSoftwareFoundation.Python.3.8_qbz5n2kfra8p0\LocalCache\local-packages\Python38\site-packages\pymysql\connections.py", line 684, in _read_packet
    packet.check_error()
  File "C:\Users\User\AppData\Local\Packages\PythonSoftwareFoundation.Python.3.8_qbz5n2kfra8p0\LocalCache\local-packages\Python38\site-packages\pymysql\protocol.py", line 220, in check_error
    err.raise_mysql_exception(self._data)
  File "C:\Users\User\AppData\Local\Packages\PythonSoftwareFoundation.Python.3.8_qbz5n2kfra8p0\LocalCache\local-packages\Python38\site-packages\pymysql\err.py", line 109, in raise_mysql_exception
    raise errorclass(errno, errval)
pymysql.err.IntegrityError: (1452, 'Cannot add or update a child row: a foreign key constraint fails (`product_new1`.`product_features_value`, CONSTRAINT `id_product` FOREIGN KEY (`id_product`) REFERENCES `product_features_value` (`id_feature_value`) ON DELETE CASCADE ON UPDATE CASCADE)')
