[2020-04-28 21:09:32,862][ERROR][logg.add_row_to_products:293] No search   ()
Traceback (most recent call last):
  File "mysqlCon.py", line 273, in add_row_to_products
    con.commit()
NameError: name 'con' is not defined
[2020-04-28 21:09:32,863][ERROR][logg.main:397] Error connect to Mysql   ()
Traceback (most recent call last):
  File "mysqlCon.py", line 392, in main
    print(con.add_row_to_products('ddddd','83838833838',40.0,10,14, 3, '11.03.2020', 20))
  File "mysqlCon.py", line 295, in add_row_to_products
    return data_dict
UnboundLocalError: local variable 'data_dict' referenced before assignment
