[2020-04-28 16:27:19,525][ERROR][logg.relative_category:235] No search   ()
Traceback (most recent call last):
  File "mysqlCon.py", line 222, in relative_category
    raise self.TooManyObjects
MySqlCon.TooManyObjects
[2020-04-28 16:27:19,527][ERROR][logg.main:306] Error connect to Mysql   ()
Traceback (most recent call last):
  File "mysqlCon.py", line 302, in main
    print(con.relative_category("одежда"))
  File "mysqlCon.py", line 236, in relative_category
    return data_dict
UnboundLocalError: local variable 'data_dict' referenced before assignment
