[2020-04-29 00:45:25,833][ERROR][logg.main:402] Error connect to Mysql   ()
Traceback (most recent call last):
  File "mysqlCon.py", line 397, in main
    print(con.add_row_to_products('ddddd','838388338389',40.0,10,14, '11.03.2020', 20))
  File "mysqlCon.py", line 298, in add_row_to_products
    return json_response({'status' : 'ok', 'message': 'Added'}, status=200)
NameError: name 'json_response' is not defined
